<type 'exceptions.Exception'>
Python 2.7.1+: /usr/bin/python
Fri Aug  5 23:49:17 2011

A problem occurred in a Python script.  Here is the sequence of
function calls leading up to the error, in the order they occurred.

 /home/chow/Applications/sonospy/sonospy/utest_scan.py in <module>()
  119     g_command_line_repair = 'some other crap'
  120     g_command_line_update_scan = 'some other crap'
  121     raise Exception, '# REMOVE EXCEPTION when set up for linux'
  122 else:
  123     g_command_line_scan = 'some other crap'
builtinException = <type 'exceptions.Exception'>
<type 'exceptions.Exception'>: # REMOVE EXCEPTION when set up for linux
    __class__ = <type 'exceptions.Exception'>
    __delattr__ = <method-wrapper '__delattr__' of exceptions.Exception object>
    __dict__ = {}
    __doc__ = 'Common base class for all non-exit exceptions.'
    __format__ = <built-in method __format__ of exceptions.Exception object>
    __getattribute__ = <method-wrapper '__getattribute__' of exceptions.Exception object>
    __getitem__ = <method-wrapper '__getitem__' of exceptions.Exception object>
    __getslice__ = <method-wrapper '__getslice__' of exceptions.Exception object>
    __hash__ = <method-wrapper '__hash__' of exceptions.Exception object>
    __init__ = <method-wrapper '__init__' of exceptions.Exception object>
    __new__ = <built-in method __new__ of type object>
    __reduce__ = <built-in method __reduce__ of exceptions.Exception object>
    __reduce_ex__ = <built-in method __reduce_ex__ of exceptions.Exception object>
    __repr__ = <method-wrapper '__repr__' of exceptions.Exception object>
    __setattr__ = <method-wrapper '__setattr__' of exceptions.Exception object>
    __setstate__ = <built-in method __setstate__ of exceptions.Exception object>
    __sizeof__ = <built-in method __sizeof__ of exceptions.Exception object>
    __str__ = <method-wrapper '__str__' of exceptions.Exception object>
    __subclasshook__ = <built-in method __subclasshook__ of type object>
    __unicode__ = <built-in method __unicode__ of exceptions.Exception object>
    args = ('# REMOVE EXCEPTION when set up for linux',)
    message = '# REMOVE EXCEPTION when set up for linux'

The above is a description of an error in a Python program.  Here is
the original traceback:

Traceback (most recent call last):
  File "utest_scan.py", line 121, in <module>
    raise Exception, '# REMOVE EXCEPTION when set up for linux'
Exception: # REMOVE EXCEPTION when set up for linux

